Workbook

Sheet setup
A1: прокачка от Глеба 12.10
A2: https://docs.google.com/spreadsheets/d/1HngiYH7XqDmkS6cOoHXfodYLnzb36POfgLcOwnP4Q4E/edit?gid=442452222#gid=442452222
A4: прокачка метриксовая 04.10
A5: https://metrics.yandex-team.ru/crons/100698/runs?pageSize=500
A7: корзинка
A8: https://metrics.yandex-team.ru/baskets/1006903/queries
A10: инструкция
A11: https://wiki.yandex-team.ru/users/dashborisova/srochnyjj-sbs-video/

Sheet results
A1: Статистика по разметке AI-тренеров
A2: Показатель | B2: Значение | C2: Как считается
A3: Число размеченных строк | B3: =SUM(B4:B6) -> 99 | C3: Число строк с распознанным вердиктом в I: победа Yandex 04.10, победа Yandex 12.10 или ничья. Сумма B4:B6; пустые и другие значения исключены.
A4: Победы Yandex 04.10 | B4: =COUNTIF('markup 12.10'!I3:I1000,"Yandex 04.10") -> 28 | C4: Число вердиктов «Yandex 04.10» в I.
A5: Победы Yandex 12.10 | B5: =COUNTIF('markup 12.10'!I3:I1000,"Yandex 12.10") -> 21 | C5: Число вердиктов «Yandex 12.10» в I.
A6: Ничьи | B6: =COUNTIF('markup 12.10'!I3:I1000,"Ничья") -> 50 | C6: Число вердиктов «Ничья» в I.
A7: Винрейт Yandex 04.10 | B7: =IF(B3=0,"—",(B4+0.5*B6)/B3) -> 0.53535354 | C7: (Победы Yandex 04.10 + 0,5 × ничьи) / число распознанных вердиктов I. Шкала 0–1; без вердиктов — «—».
A8: Винрейт Yandex 12.10 | B8: =IF(B3=0,"—",(B5+0.5*B6)/B3) -> 0.46464646 | C8: (Победы Yandex 12.10 + 0,5 × ничьи) / число распознанных вердиктов I. Шкала 0–1; без вердиктов — «—».
A9: Средний скор Yandex 04.10 | B9: =IFERROR(__xludf.DUMMYFUNCTION("LET(scores,ARRAYFORMULA(IFERROR(VALUE('markup 12.10'!J3:J1000),0)),IFERROR(AVERAGE(FILTER(scores,scores>=1,scores<=5,ARRAYFORMULA(MOD(scores,1)=0))),""—""))"),3.757575757575758) -> 3.7575758 | C9: Среднее целых оценок 1–5 в K; текстовые числа учитываются. Пустые и некорректные оценки исключены. Знаменатель — B11; без оценок — «—».
A10: Средний скор Yandex 12.10 | B10: =IFERROR(__xludf.DUMMYFUNCTION("LET(scores,ARRAYFORMULA(IFERROR(VALUE('markup 12.10'!K3:K1000),0)),IFERROR(AVERAGE(FILTER(scores,scores>=1,scores<=5,ARRAYFORMULA(MOD(scores,1)=0))),""—""))"),3.717171717171717) -> 3.7171717 | C10: Среднее целых оценок 1–5 в L; текстовые числа учитываются. Пустые и некорректные оценки исключены. Знаменатель — B12; без оценок — «—».
A11: Число оценок Yandex 04.10 | B11: {=LET(scores,IFERROR(VALUE('markup 12.10'!J3:J1000),0),SUMPRODUCT((scores>=1)*(scores<=5)*MOD(scores,1)=0))} -> 99 | C11: Число корректных целых оценок 1–5 в K, включая текстовые числа. Считается независимо от заполненности вердикта I.
A12: Число оценок Yandex 12.10 | B12: {=LET(scores,IFERROR(VALUE('markup 12.10'!K3:K1000),0),SUMPRODUCT((scores>=1)*(scores<=5)*MOD(scores,1)=0))} -> 99 | C12: Число корректных целых оценок 1–5 в L, включая текстовые числа. Считается независимо от заполненности вердикта I.
A13: Сломанные выдачи Yandex 12.10 | B13: =COUNTIF('markup 12.10'!L3:L1000,"Да") -> 8 | C13: Число ответов «Да» в M — Yandex 12.10 признан сломанным.
A14: Выдачи с оценкой поломки | B14: =COUNTIF('markup 12.10'!L3:L1000,"Да")+COUNTIF('markup 12.10'!L3:L1000,"Нет") -> 99 | C14: Число ответов «Да» или «Нет» в M. Пустые и другие значения исключены; знаменатель доли поломок.
A15: Доля сломанных выдач Yandex 12.10 | B15: =IF(B14=0,"—",B13/B14) -> 0.080808081 | C15: B13 / B14: число «Да» в M / число ответов «Да» или «Нет» в M. Пустой ответ не означает «Нет»; без ответов — «—».
A17: Проблемы с YouTube
A18: Показатель | B18: Значение | C18: Как считается
A19: Число ответов о YouTube | B19: =SUM(B20:B23) -> 99 | C19: Число ответов из четырёх вариантов в N; пустые и другие значения исключены. Независимо от вердикта I.
A20: Нет проблем | B20: =COUNTIF('markup 12.10'!M3:M1000,"нет") -> 45 | C20: Число ответов «нет» в N.
A21: Проблемы только 04.10 | B21: =COUNTIF('markup 12.10'!M3:M1000,"только 04.10") -> 7 | C21: Число ответов «только 04.10» в N.
A22: Проблемы только 12.10 | B22: =COUNTIF('markup 12.10'!M3:M1000,"только 12.10") -> 13 | C22: Число ответов «только 12.10» в N.
A23: Проблемы у обоих серпов | B23: =COUNTIF('markup 12.10'!M3:M1000,"у обоих серпов") -> 34 | C23: Число ответов «у обоих серпов» в N.
A24: Доля проблем: Yandex 04.10 | B24: =IF(B19=0,"—",(B21+B23)/B19) -> 0.41414141 | C24: (Только 04.10 + у обоих серпов) / число ответов B19. Шкала 0–1; без ответов — «—».
A25: Доля проблем: Yandex 12.10 | B25: =IF(B19=0,"—",(B22+B23)/B19) -> 0.47474747 | C25: (Только 12.10 + у обоих серпов) / число ответов B19. Шкала 0–1; без ответов — «—».
A26: Доля с любой проблемой | B26: =IF(B19=0,"—",SUM(B21:B23)/B19) -> 0.54545455 | C26: (Только 04.10 + только 12.10 + у обоих серпов) / B19. Пустой ответ не означает «нет»; без ответов — «—».

Sheet markup 12.10
B1: Информация о запросе | E1: Прокачка | G1: Разметка AI-тренера
A2: query | B2: region | C2: device | D2: likbez | E2: url | F2: ок / не ок | G2: login | H2: Баг прокачки? | I2: Кто выиграл | J2: Оценка Yandex 04.10 | K2: Оценка Yandex 12.10 | L2: Поиск сломанный 12.10? | M2: Проблемы с Youtube | N2: Комментарий
A3: чем закончится игра в кальмара 3сезон | B3: Центральный федеральный округ (3) | C3: ANDROID | D3: О ЧЕМ ЗАПРОС: Запрос касается возможного завершения 3 сезона южнокорейского сериала «Игра в кальмара» (2021, режиссёр Хван Дон Хёк). Однако на данный момент существует только 1 сезон, и о выходе 3 сезона официальных данных нет. ОСНОВНОЙ ИНТЕНТ: Посмотреть видео с разбором или предположениями о возможном завершении 3 сезона сериала «Игра в кальмара» (если такие видео существуют). ВТОРИЧНЫЙ ИНТЕНТ: ['Найти видео с обсуждением финала 1 сезона «Игры в кальмара» (так как 3 сезон не существует).', 'Посмотреть трейлеры, интервью или новости о возможном продолжении сериала.', 'Узнать фанатские теории или спойлеры о развитии сюжета, если бы 3 сезон был снят.'] | E3: Открыть HTML | F3: ок | G3: ulyana1993 | H3: Нет | I3: Ничья | J3: 5 | K3: 5 | L3: Нет | M3: нет | N3: Примерно одинаковые выдачи. Все видео релевантны. Обычные каналы про фильмы.
A4: новые видио рыжива ката | B4: Калининград (22) | C4: DESKTOP | D4: О ЧЕМ ЗАПРОС: Пользователь ищет новые видео, связанные с 'рыжива ката'. Точный контекст или значение этого термина неизвестны, возможно, это опечатка или узкоспециализированный запрос. ОСНОВНОЙ ИНТЕНТ: Найти новые видео, связанные с 'рыжива ката' (возможно, опечатка или специфический термин). ВТОРИЧНЫЙ ИНТЕНТ: ["Найти видео с похожими или альтернативными названиями, если 'рыжива ката' — опечатка.", "Найти обзоры или поясняющие ролики, если 'рыжива ката' — это термин из какой-либо нишевой тематики."] | E4: Открыть HTML | F4: ок | G4: ulyana1993 | H4: Нет | I4: Ничья | J4: 1 | K4: 1 | L4: Нет | M4: нет | N4: https://vkvideo.ru/@rizhiykottv Обе выдачи неактуальны. Нет ни одного нового видео. Видео выходят часто. Поэтому актуальность важна (условно не старше 2 месяцев, в идеале месяц).
A5: дай мне посмотреть | B5: Южный федеральный округ (26) | C5: DESKTOP | D5: О ЧЕМ ЗАПРОС: Запрос связан с поиском видео, содержащего трек «Дай мне посмотреть» (Let Me See) от Bushido Zho и Heronwater, выпущенный в 2023 году. ОСНОВНОЙ ИНТЕНТ: Найти видео с треком «Дай мне посмотреть» (Let Me See) для прослушивания или просмотра клипа. ВТОРИЧНЫЙ ИНТЕНТ: ['Посмотреть клип или музыкальное видео на этот трек, если оно существует.', 'Найти живые выступления или каверы на этот трек.', 'Узнать больше о Bushido Zho и Heronwater, связанные с этим треком.'] | E5: Открыть HTML | F5: ок | G5: abrelis | H5: Нет | I5: Ничья | J5: 4 | K5: 4 | L5: Нет | M5: только 04.10 | N5: Обе выдачи хорошо решают ОИ, у левого дефект - лишний ютуб, у правого - неподходящий источник на В5 (мобильные игры)
A6: зубарев | B6: Тула (15) | C6: DESKTOP | D6: О ЧЕМ ЗАПРОС: Запрос относится к Александру Зубареву — видеоблогеру, тиктокеру и стримеру, известному своими роликами о жизни в Китае, местной культуре и быте. Он также участвовал в различных шоу и снимается в кино. ОСНОВНОЙ ИНТЕНТ: Найти видео с Александром Зубаревым: его блоги, стримы, выступления в шоу или ролики о жизни в Китае. ВТОРИЧНЫЙ ИНТЕНТ: ['Посмотреть интервью или участия Зубарева в шоу (например, «Плюшки», «Вопрос ребром»).', 'Узнать о его личной жизни или творческих проектах (например, фильм «Скуф»).', 'Найти контент, связанный с культурой и бытом Китая, в его подаче.'] | E6: Открыть HTML | F6: ок | G6: abrelis | H6: Нет | I6: Ничья | J6: 5 | K6: 5 | L6: Нет | M6: нет | N6: Обе выдачи решают ОИ на каждой странице на рел+ от официального источника
A7: купить подарки аватария | B7: Самара (51) | C7: IPHONE | D7: О ЧЕМ ЗАПРОС: Запрос связан с поиском способов приобретения виртуальных подарков для игры «Аватария». Пользователь, вероятно, хочет найти магазины или сервисы, где можно купить внутриигровые подарки. ОСНОВНОЙ ИНТЕНТ: Найти видео с обзором или инструкцией, как и где купить подарки в игре «Аватария». ВТОРИЧНЫЙ ИНТЕНТ: ['Посмотреть видео о том, как работают магазины подарков в «Аватарии» (например, обзор Telegram-каналов или сайтов).', 'Узнать о промокодах или акциях, связанных с подарками в игре, через видео-контент.', 'Найти видео с отзывами или рекомендациями о покупке подарков в «Аватарии».'] | E7: Открыть HTML | F7: ок | G7: vlodster | H7: Нет | I7: Yandex 12.10 | J7: 3 | K7: 4 | L7: Нет | M7: у обоих серпов | N7: Практически схожие выдачи, но у Новой в топ-1 имеется видеоролик с ОК, в то время как у старой с Ютуба (что, по сути, является серьезным дефектом) -> победа новой (проблемы с ютубом имеются у обоих серпов)
A8: можно ли использовать аккаунт huawei в смартфоне другой м | B8: Санкт-Петербург (2) | C8: ANDROID | D8: О чем запрос: можно ли использовать аккаунт huawei в смартфоне другой м Основной интент: видео с ответом на вопрос Вторичный интент: | E8: Открыть HTML | F8: ок | G8: vetervi | H8: Нет | I8: Ничья | J8: 3 | K8: 3 | L8: Нет | M8: у обоих серпов | N8: Выдачи почти не различаются, ответа на запрос нет ни там ни там
A9: кто тебе это сказал виа караоке | B9: Уфа (172) | C9: DESKTOP | D9: О ЧЕМ ЗАПРОС: Запрос связан с поиском видео караоке-версии песни «Кто тебе сказал» в исполнении ВИА «Лейся, песня!». ОСНОВНОЙ ИНТЕНТ: Найти видео с караоке-версией песни «Кто тебе сказал» ВИА «Лейся, песня!» для прослушивания или исполнения. ВТОРИЧНЫЙ ИНТЕНТ: ['Посмотреть оригинальное исполнение песни «Кто тебе сказал» ВИА «Лейся, песня!»', 'Найти другие караоке-версии песен ВИА «Лейся, песня!»', 'Узнать больше о творчестве ВИА «Лейся, песня!»'] | E9: Открыть HTML | F9: ок | G9: vetervi | H9: Нет | I9: Yandex 12.10 | J9: 3 | K9: 4 | L9: Нет | M9: только 12.10 | N9: В старом одно видео не караоке, ещё одно удалено, три по теме. В новом: три караоке под минус, одно под плюс, одно недоступно (ютуб).
A10: audi lucky blocks моды из ярика лапы | B10: Городской округ Орехово-Зуево (120990) | C10: DESKTOP | D10: О ЧЕМ ЗАПРОС: Запрос связан с модами для игры Minecraft, в частности с модификацией Lucky Blocks, которая добавляет в игру блоки удачи с различными случайными событиями. Возможно, пользователь ищет видео, связанные с установкой, обзором или геймплеем этих модов. ОСНОВНОЙ ИНТЕНТ: Найти видео, связанные с модом Lucky Blocks для Minecraft, возможно, обзоры, геймплей или инструкции по установке. ВТОРИЧНЫЙ ИНТЕНТ: ["Посмотреть видео с геймплеем мода Youtuber's Lucky Blocks", 'Найти обзоры на различные версии мода Lucky Blocks', 'Узнать, как установить мод Lucky Blocks в Minecraft'] | E10: Открыть HTML | F10: ок | G10: vlodster | H10: Нет | I10: Ничья | J10: 2 | K10: 2 | L10: Нет | M10: у обоих серпов | N10: Не особо понятно, что требуется пользователю из-за слова "audi". В остальном на обоих серпах представлены обзоры/игры с лаки блоками от Ярика Лапы. Имеется минорный плюс в сторону новой выдачи - имеется материал с доступных платформ (но они также решают ВИ, так как упоминания "audi" нигде не найдено) -> ничья. Если же опираться на ликбез, то оба серпа решают ОИ, но у новой выдачи больше материала из доступных без впн источников
A11: разбили китайца, моя жизнь изменится навсегда - 11 часть | B11: Россия (225) | C11: DESKTOP | D11: О ЧЕМ ЗАПРОС: Пользователь ищет 11-ю часть видео, связанного с событием или историей под названием «Разбили китайца, моя жизнь изменится навсегда». Контекст запроса указывает на то, что это может быть серия из какого-то веб-сериала, блог-поста или документального рассказа, где описывается значимое событие в жизни автора или героя. ОСНОВНОЙ ИНТЕНТ: Найти и посмотреть 11-ю часть видео «Разбили китайца, моя жизнь изменится навсегда». ВТОРИЧНЫЙ ИНТЕНТ: ['Узнать больше о предыдущих или последующих частях этого видео (если таковые существуют).', 'Понять контекст или содержание всей серии, чтобы разобраться в сюжете.'] | E11: Открыть HTML | F11: ок | G11: abraamian | H11: Нет | I11: Ничья | J11: 5 | K11: 5 | L11: Нет | M11: нет | N11: Выдачи полностью идентичны
A12: джигеротта грешница | B12: Кострома (7) | C12: ANDROID | D12: О ЧЕМ ЗАПРОС: Запрос посвящён персонажу Джиггероте Грешнице из сериала «Лексс» (1997–2002), её роли в сюжете и ключевым моментам появления в сериале. ОСНОВНОЙ ИНТЕНТ: Найти видео с участием Джиггероты Грешницы в сериале «Лексс» (эпизоды, сцены, моменты с её участием). ВТОРИЧНЫЙ ИНТЕНТ: ['Посмотреть обзоры или анализ персонажа Джиггероты (например, её влияние на сюжет, особенности поведения).', 'Узнать больше об актрисе Эллен Дубин и её работе над ролью (интервью, закулисные материалы).', 'Найти трейлеры или фрагменты сериала «Лексс», где фигурирует Джиггерота.'] | E12: Открыть HTML | F12: ок | G12: latushinskaya | H12: Нет | I12: Ничья | J12: 1 | K12: 1 | L12: Да | M12: нет | N12: В обеих выдачах нерел. (совершенно другой сериал)
A13: геннадий синицын маньяк | B13: Рязань (11) | C13: IPHONE | D13: О ЧЕМ ЗАПРОС: Запрос касается Геннадия Синицына, серийного маньяка из Волгограда, обвиняемого в серии изнасилований и убийств в прошлом. Он был осужден, но позже срок заменили на 15 лет колонии, после чего он вышел на свободу. ОСНОВНОЙ ИНТЕНТ: Найти видео о Геннадии Синицыне, его преступлениях, суде и последующем освобождении (документальные фильмы, репортажи, интервью). ВТОРИЧНЫЙ ИНТЕНТ: ['Посмотреть криминальные анализы или расследования его дела.', 'Узнать о реакции общества и СМИ на его преступления и освобождение.', 'Найти интервью с жертвами, свидетелями или экспертами по этому делу.'] | E13: Открыть HTML | F13: ок | G13: latushinskaya | H13: Нет | I13: Ничья | J13: 3 | K13: 3 | L13: Нет | M13: только 12.10 | N13: Вероятно, П перепутал фамилию маньяка. В старой выдаче 1 видео недоступно, в новой на 4 позиции очень плохой нерел. (не назвать шокирующим, но есть мат). Ничья, т.к. дефекты сопоставимы, а интент не решен в обеих выдачах.
A14: как узнать что порвана подушка двигателя лексус джи эс 300 2006 | B14: Астрахань (37) | C14: ANDROID | D14: О ЧЕМ ЗАПРОС: Запрос касается диагностики неисправности подушек двигателя в автомобиле Lexus GS 300 2006 года. Пользователь хочет узнать признаки, указывающие на повреждение подушек двигателя. ОСНОВНОЙ ИНТЕНТ: Найти видео с инструкцией или объяснением, как определить, что подушка двигателя Lexus GS 300 2006 года порвана. ВТОРИЧНЫЙ ИНТЕНТ: ['Посмотреть видео с обзором общих признаков неисправности подушек двигателя в автомобилях.', 'Найти видео с демонстрацией замены подушек двигателя на Lexus GS 300.', 'Посмотреть видео с советами по диагностике автомобильных неисправностей своими руками.'] | E14: Открыть HTML | F14: ок | G14: latushinskaya | H14: Да
A15: трахает зрелую в жопу | B15: Москва (213) | C15: ANDROID | D15: О ЧЕМ ЗАПРОС: Запрос связан с поиском видео порнографического содержания, где демонстрируется анальный секс со зрелыми женщинами. Контент предназначен исключительно для взрослой аудитории. ОСНОВНОЙ ИНТЕНТ: Найти видео с анальным сексом, где участвуют зрелые женщины. ВТОРИЧНЫЙ ИНТЕНТ: ['Посмотреть альтернативные видео с похожим содержанием (например, с другими участниками или в других жанрах).', 'Найти сайты или платформы, специализирующиеся на подобном контенте.'] | E15: Открыть HTML | F15: ок | G15: latushinskaya | H15: Нет | I15: Yandex 12.10 | J15: 3 | K15: 5 | L15: Нет | M15: нет | N15: В старой выдаче 1 и 3 ролики недоступны, поэтому побеждает новая выдача с доступным контентом, который релевантен.
A16: при какой максимальной температуре воздуха может работать сварщик | B16: Вешки (117530) | C16: IPHONE | D16: О ЧЕМ ЗАПРОС: Запрос касается допустимых температурных условий для работы сварщиков, включая верхние пределы температуры в зависимости от категории работ и требования к экипировке при минусовых температурах. ОСНОВНОЙ ИНТЕНТ: Найти видео с объяснением допустимых температурных условий для работы сварщиков, включая нормы СанПиН и рекомендации по работе в экстремальных условиях. ВТОРИЧНЫЙ ИНТЕНТ: ['Посмотреть видео о влиянии температуры на качество сварки и безопасность работ.', 'Найти обзоры на специальную экипировку для сварщиков, работающих в условиях высоких или низких температур.', 'Узнать о дополнительных нормах и правилах работы сварщиков в разных климатических условиях.'] | E16: Открыть HTML | F16: ок | G16: latushinskaya | H16: Нет | I16: Yandex 04.10 | J16: 3 | K16: 3 | L16: Нет | M16: у обоих серпов | N16: В обеих выдачах по 1 ссылке на «Ютуб» (в старой тот же контент на «Рутуб», что в правой, но есть другая ссылка на «Ютуб»). Также в старой ютуб-видео ранжировано ниже. = слабая победа старой.
A17: штребух teil 735 | B17: Оренбург (48) | C17: ANDROID | D17: О ЧЕМ ЗАПРОС: Запрос, вероятно, связан с контентом автора YouTube-канала ШТРЭБУХ, который специализируется на видео о находках на помойках. Возможно, пользователь ищет конкретное видео или серию (teil 735), но точной информации об этом нет. ОСНОВНОЙ ИНТЕНТ: Найти видео с YouTube-канала ШТРЭБУХ, возможно, конкретный ролик или серию под номером 735. ВТОРИЧНЫЙ ИНТЕНТ: ['Познакомиться с контентом канала ШТРЭБУХ (обзоры находок, тематические видео)', 'Узнать больше о деятельности автора (например, его соцсети, другие платформы)', 'Найти похожие каналы или видео о находках на помойках'] | E17: Открыть HTML | F17: ок | G17: latushinskaya | H17: Нет | I17: Yandex 12.10 | J17: 3 | K17: 4 | L17: Нет | M17: только 04.10 | N17: Победа новой выдаче, т.к. в старой 2 ролика недоступны («ютуб»). Оценка снижена, т.к. контент не самый свежий.
A18: игра в кальмара прон тг | B18: Солоновка (124100) | C18: ANDROID | D18: О ЧЕМ ЗАПРОС: Пользователь ищет видео с материалами сексуального характера (порнографического содержания), связанными с сериалом 'Игра в кальмара'. Запрос предполагает, что контент может быть размещен в Telegram или других платформах. ОСНОВНОЙ ИНТЕНТ: Найти порнографические видео, вдохновленные сериалом 'Игра в кальмара' или содержащие его тематику. ВТОРИЧНЫЙ ИНТЕНТ: ['Посмотреть обсуждения или разборы подобного контента (например, статьи или видео-анализ)', 'Найти ссылки на Telegram-каналы или другие платформы с подобными материалами', 'Узнать, существуют ли пародии или альтернативные версии сцен из сериала в подобном жанре'] | E18: Открыть HTML | F18: ок | G18: latushinskaya | H18: Нет | I18: Ничья | J18: 5 | K18: 5 | L18: Нет | M18: нет | N18: Ничья, т.к. нет явных преимуществ какой-либо из выдач: в обеих ролики релевантны и доступны
A19: врестболл | B19: Махачкала (28) | C19: DESKTOP | D19: О ЧЕМ ЗАПРОС: Запрос касается игры «врестболл» (wrestball) — гибрида баскетбола и борьбы, где участники зарабатывают очки как за забитые мячи, так и за успешные приёмы борьбы. Игра проходит в три тайма по 10 минут, с возможностью досрочного завершения при наборе 16 очков. Игроки используют защитную экипировку из-за высокой травмоопасности. ОСНОВНОЙ ИНТЕНТ: Найти видео с правилами, демонстрацией или матчами по врестболлу. ВТОРИЧНЫЙ ИНТЕНТ: ['Посмотреть обучающие видео по технике игры или борьбы в врестболе.', 'Узнать о защитной экипировке для врестбола и её использовании.', 'Найти записи соревнований или турниров по врестболлу.'] | E19: Открыть HTML | F19: ок | G19: vlodster | H19: Нет | I19: Ничья | J19: 4 | K19: 4 | L19: Нет | M19: у обоих серпов | N19: У обоих серпов рел видео + у обоих имеются проблемы с наличием ютуба (+-на одном уровне) -> ничья
A20: дом студио скибиди туалет | B20: Санкт-Петербург и Ленинградская область (10174) | C20: DESKTOP | D20: О ЧЕМ ЗАПРОС: Пользователь ищет видео, связанные с анимацией «Скибиди туалет», созданной студией DOM Studio. Это популярная интернет-анимация, которая распространяется через различные платформы, включая Telegram, Rutube и TikTok. В запросе упоминается конкретная студия и название анимации. ОСНОВНОЙ ИНТЕНТ: Найти видео с анимацией «Скибиди туалет» от студии DOM Studio, включая полные эпизоды или специальные выпуски (например, «skibidi toilet multiverse (Christmas Special)»). ВТОРИЧНЫЙ ИНТЕНТ: ['Посмотреть другие работы DOM Studio, связанные с «Скибиди туалет» (например, «skibidi toilet multiverse 01–020 (all episodes)»).', 'Найти новости или дополнительные материалы о «Скибиди туалет» в Telegram-канале студии или на других платформах.', 'Узнать о других проектах или анимациях DOM Studio, помимо «Скибиди туалет».'] | E20: Открыть HTML | F20: ок | G20: vlodster | H20: Нет | I20: Ничья | J20: 4 | K20: 4 | L20: Нет | M20: только 12.10 | N20: У обоих серпов схожие выдачи, но в топ-5 у Олда видео недоступно (в то время как у нового имеется дубль рел видео) -> ничья
A21: семь смертных грехов 4 сезон все серии | B21: Краснодар (35) | C21: DESKTOP | D21: О ЧЕМ ЗАПРОС: Запрос касается 4-го сезона аниме «Семь смертных грехов: Яростное правосудие», который вышел в 2021 году и состоит из 24 серий. Пользователь ищет все серии этого сезона в видеоформате. ОСНОВНОЙ ИНТЕНТ: Посмотреть все серии 4-го сезона аниме «Семь смертных грехов: Яростное правосудие» в полном объёме. ВТОРИЧНЫЙ ИНТЕНТ: ['Найти альтернативные платформы для просмотра 4-го сезона (например, Jut Su, animego.me).', 'Узнать дополнительную информацию о сезоне (даты выхода, количество серий).', 'Посмотреть трейлеры или обзоры 4-го сезона.'] | E21: Открыть HTML | F21: ок | G21: enling | H21: Нет | I21: Ничья | J21: 2 | K21: 2 | L21: Нет | M21: нет | N21: Одинаковые выдачи, те же самые видео с одних и тех же каналов. Нет видео, где были бы все серии 4 сезона в одном видео, хотя такие существуют.
A22: как убить нефтяного старейшину | B22: Татариново (120161) | C22: ANDROID | D22: О ЧЕМ ЗАПРОС: Запрос касается способа победы над персонажем или существом по имени «нефтяной старейшина» в каком-то медиапродукте (игре, фильме, сериале и т. д.). ОСНОВНОЙ ИНТЕНТ: Найти видео, объясняющее, как победить «нефтяного старейшину» (например, гайд по прохождению, тактику в игре или сцену из фильма/сериала). ВТОРИЧНЫЙ ИНТЕНТ: ['Посмотреть обзор или анализ сцены/битвы с «нефтяным старейшиной».', 'Узнать больше о самом персонаже (его происхождении, способностях и роли в сюжете).', 'Найти альтернативные методы или скрытые механики, связанные с этим противником.'] | E22: Открыть HTML | F22: ок | G22: enling | H22: Нет | I22: Yandex 04.10 | J22: 4 | K22: 4 | L22: Нет | M22: у обоих серпов | N22: Обе выдачи с ненужными Youtube видео (аналоги есть на доступных платформах). Но вместо 2 в первой, во второй уже 3 Youtube видео.
A23: секс сексуальный секс | B23: Элиста (1094) | C23: ANDROID | D23: О ЧЕМ ЗАПРОС: Пользователь ищет видео с материалами сексуального характера (порнографического содержания), предназначенные для взрослой аудитории. ОСНОВНОЙ ИНТЕНТ: Найти видео с порнографическим контентом для взрослых. ВТОРИЧНЫЙ ИНТЕНТ: ['Посмотреть тематические подборки или категории порнографических видео.', 'Найти сайты или платформы, специализирующиеся на подобном контенте.'] | E23: Открыть HTML | F23: ок | G23: enling | H23: Нет | I23: Ничья | J23: 5 | K23: 5 | L23: Нет | M23: нет | N23: Из 5 порно видео в первой выдаче совпадает со второй только одно, но 4 новых такого же качества.
A24: таро дрим | B24: Липецк (9) | C24: IPHONE | D24: О ЧЕМ ЗАПРОС: Запрос может быть связан с картами Таро, возможно, с колодой или системой под названием 'Дрим', либо с толкованием снов с использованием Таро. ОСНОВНОЙ ИНТЕНТ: Найти видео, связанное с картами Таро 'Дрим' (например, обзор колоды, расклады, толкование снов с их помощью). ВТОРИЧНЫЙ ИНТЕНТ: ['Посмотреть общие видео о Таро и их использовании в толковании снов.', 'Найти обучающие материалы по работе с картами Таро, включая необычные колоды.'] | E24: Открыть HTML | F24: ок | G24: alannas | H24: Нет | I24: Yandex 04.10 | J24: 5 | K24: 4 | L24: Нет | M24: нет | N24: Обе выдачи релевантные, но в выдаче от 12.10 старые видео стоятв топ-1,2, думаю пользователю нужны более свежие выше
A25: клумба | B25: Ставропольский край (11069) | C25: DESKTOP | D25: О ЧЕМ ЗАПРОС: Запрос касается клумб — декоративных участков для выращивания растений с продуманной композицией. Пользователь, вероятно, ищет информацию о создании, оформлении или уходе за клумбами, включая выбор растений и их расположение. ОСНОВНОЙ ИНТЕНТ: Найти видео о создании, оформлении или уходе за клумбами, включая выбор растений и их расположение. ВТОРИЧНЫЙ ИНТЕНТ: ['Посмотреть видео о различных типах клумб (регулярные, нерегулярные, миксбордеры и др.).', 'Узнать о комбинациях растений для клумб с непрерывным цветением.', 'Найти советы по выбору места и подготовке почвы для клумбы.'] | E25: Открыть HTML | F25: ок | G25: alannas | H25: Нет | I25: Yandex 04.10 | J25: 5 | K25: 3 | L25: Нет | M25: только 12.10 | N25: В выдаче от 12.10 Ютуб в топ-1 и 4, кроме того в топ-2 непопулярное
A26: ну погоди на русскм 16 выпуск | B26: Сосьва (110311) | C26: DESKTOP | D26: О ЧЕМ ЗАПРОС: Пользователь ищет шестнадцатый выпуск советского мультсериала «Ну, погоди!» (1986), режиссёра Вячеслава Котёночкина. В этом выпуске Волк, получив солнечный удар, воображает погоню за Зайцем по сюжетам известных сказок. Мультфильм длится 10 минут и озвучен на русском языке. ОСНОВНОЙ ИНТЕНТ: Посмотреть 16-й выпуск мультсериала «Ну, погоди!» (1986) полностью. ВТОРИЧНЫЙ ИНТЕНТ: ['Найти трейлер или фрагменты 16-го выпуска «Ну, погоди!»', 'Узнать больше о создании этого выпуска (например, интервью с создателями)', 'Посмотреть другие выпуски мультсериала «Ну, погоди!»'] | E26: Открыть HTML | F26: ок | G26: ulesovai | H26: Нет | I26: Yandex 12.10 | J26: 4 | K26: 5 | L26: Нет | M26: нет | N26: В выдаче от 04.10 четыре видео рел+ (1986 г.), а второе видео рел- (Ну, погоди! Каникулы 16 выпуск). Кроме того, в выдаче есть два видео на платформе ВК, но от разных публикаторов. Четвертое и пятое видео в аднной выдаче низкого качества (360р). В выдаче от 12.10 все ролики рел+. Качество третьего и четвертого видео 360р. Остальные минимум 720 р. ЮТ нет, он и не требуется.
... A66: wps office что это за программа | B66: Москва (213) | C66: DESKTOP | D66: О ЧЕМ ЗАПРОС: WPS Office — это офисный пакет, включающий текстовый редактор, таблицы и презентации, аналог Microsoft Office. Разработан китайской компанией Kingsoft. Популярен благодаря бесплатной версии и совместимости с форматами DOC, XLS, PPT. ОСНОВНОЙ ИНТЕНТ: Найти видео с обзором или объяснением, что такое WPS Office, её возможностей и особенностей. ВТОРИЧНЫЙ ИНТЕНТ: ['Посмотреть сравнение WPS Office с другими офисными пакетами (например, Microsoft Office, LibreOffice).', 'Узнать, как установить и настроить WPS Office.', 'Найти обучающие видео по использованию функций WPS Office.'] | E66: Открыть HTML | F66: ок | G66: abrelis | H66: Нет | I66: Yandex 04.10 | J66: 4 | K66: 4 | L66: Нет | M66: только 04.10 | N66: Левый серп: все страницы решают ОИ, но есть дефект - ютуб + есть дубль на выдаче. Правый серп: нет ютуба, но В4 только рел- и источник плохой и не подходящий. Т.к. релевантность и источник для нас важнее, левый серп считаем лучше.
A67: аир 400 лодка пвх проф марин | B67: Сия (124908) | C67: ANDROID | D67: О ЧЕМ ЗАПРОС: Пользователь ищет видео, связанные с лодкой АИР 400 ПВХ от ProfMarine. Вероятно, его интересует обзор, тест-драйв, инструкция по сборке или эксплуатации этой модели. ОСНОВНОЙ ИНТЕНТ: Найти видео с обзором, тест-драйвом или инструкцией по лодке АИР 400 ПВХ ProfMarine ВТОРИЧНЫЙ ИНТЕНТ: ['Посмотреть сравнение лодки АИР 400 с другими моделями', 'Узнать о характеристиках и особенностях этой лодки', 'Найти видео по ремонту или обслуживанию лодки АИР 400'] | E67: Открыть HTML | F67: ок | G67: abraamian | H67: Нет | I67: Ничья | J67: 4 | K67: 4 | L67: Нет | M67: нет
A68: israel | B68: Новосибирск (65) | C68: DESKTOP | D68: О ЧЕМ ЗАПРОС: Пользователь ищет видео, связанные с Израилем. Это может быть информация о стране, её достопримечательностях, истории, культуре, политике, путешествиях или других темах, связанных с Израилем. ОСНОВНОЙ ИНТЕНТ: Найти видео об Израиле (общая информация, история, культура, достопримечательности и т. д.) ВТОРИЧНЫЙ ИНТЕНТ: ['Посмотреть документальные фильмы или репортажи о Израиле', 'Найти видео о путешествиях по Израилю', 'Узнать о текущих событиях или политической ситуации в Израиле'] | E68: Открыть HTML | F68: ок | G68: latushinskaya | H68: Нет | I68: Ничья | J68: 4 | K68: 4 | L68: Нет | M68: нет | N68: Ничья, т.к. выдачи решают разные ОИ: старая решает новостной, новая – инфо о стране (в новой есть новостное видео, но оно старое). Преимущественный интент сложно выделить, инфоповоды значимые и могут быть интересны П так же, как и общая информация о стране.
A69: брюс ли фильмы | B69: Суш (185062) | C69: IPHONE | D69: О ЧЕМ ЗАПРОС: Запрос касается фильмов с участием Брюса Ли — легендарного актёра и мастера боевых искусств. В описании перечислены его основные кинокартины, включая такие известные работы, как «Путь дракона», «Кулак ярости», «Выход Дракона» и другие. Указаны жанры и годы выпуска фильмов. ОСНОВНОЙ ИНТЕНТ: Найти и посмотреть фильмы с участием Брюса Ли. ВТОРИЧНЫЙ ИНТЕНТ: ['Узнать о фильмографии Брюса Ли (например, документальные фильмы о нём).', 'Посмотреть трейлеры или обзоры фильмов с Брюсом Ли.', 'Найти редкие или менее известные работы Брюса Ли (например, сериалы «Лонгстрит» или «Зелёный Шершень»).'] | E69: Открыть HTML | F69: ок | G69: latushinskaya | H69: Нет | I69: Ничья | J69: 5 | K69: 5 | L69: Нет | M69: нет | N69: Ничья, т.к. нет явных преимуществ какой-либо из выдач: в обеих релевантные ролики без дефектов.
A70: спрячь меня турецкий сериал 21 серия | B70: Москва (213) | C70: DESKTOP | D70: О ЧЕМ ЗАПРОС: Запрос касается 21-й серии турецкого сериала «Спрячь меня» (2023–2024), которая вышла 21 марта 2024 года. В серии происходят ключевые события: конфликты между персонажами, наказание Тансу, решение Филиз о разводе и эмоциональная встреча Мете с отцом. ОСНОВНОЙ ИНТЕНТ: Посмотреть 21-ю серию турецкого сериала «Спрячь меня» ВТОРИЧНЫЙ ИНТЕНТ: ['Найти краткое содержание или обзор 21-й серии', 'Узнать, где можно посмотреть серию (например, на ivi.ru или okko.tv)', 'Посмотреть другие серии или сезоны сериала «Спрячь меня»'] | E70: Открыть HTML | F70: ок | G70: ulesovai | H70: Нет | I70: Yandex 12.10 | J70: 3 | K70: 4 | L70: Нет | M70: только 04.10 | N70: Первые четыре видео у выдач одинаковые. Разница в пятых роликах. У выдачи от 4.10 - ЮТ, 1080р HD, полная серия, русский дубляж, на канале овер 28К подписчиков. У выдачи от 12.10 - ВК Видео, отрывок из серии, всего 39 просмотров, на канале 4,4К подписчиков, максимальное качество 1080р FHD. Отдаем победу выдаче от 12.10, поскольку ЮТ здесь не нужен. Первые четыре видео вполне решают ОИ в таком же качестве как на ЮТ.
A71: ты и мембер форевер жасмин | B71: Ачинск (11302) | C71: DESKTOP | D71: О ЧЕМ ЗАПРОС: Запрос, вероятно, связан с поиском видео, содержащего фразу «ты и мембер форевер жасмин». Это может быть отсылка к песне, мему, сериалу или другому медиаконтенту, где фигурирует имя Жасмин. Точный контекст неясен из-за отсутствия дополнительной информации. ОСНОВНОЙ ИНТЕНТ: Найти видео с фразой или контентом, связанным с «ты и мембер форевер жасмин» (например, клип, мем, отрывок из шоу). ВТОРИЧНЫЙ ИНТЕНТ: ['Посмотреть связанные видео (например, обзоры, пародии, реакции на этот контент).', 'Узнать происхождение фразы (если она является мемом или цитатой).'] | E71: Открыть HTML | F71: ок | G71: abrelis | H71: Нет | I71: Ничья | J71: 1 | K71: 1 | L71: Нет | M71: у обоих серпов | N71: ОИ можно решить (как на ютуб, так и на рутуб), но ни одна выдача его не решает и в топ-1 показывает удалённый с ютуба ролик, у обоих есть проблема лишнего ютуба
A72: моя любовь к тебе чиста я просто верю в чудеса | B72: Санкт-Петербург (2) | C72: DESKTOP | D72: О ЧЕМ ЗАПРОС: Запрос связан с поиском стихотворения или песни под названием «Моя любовь к тебе чиста». Стихотворение было опубликовано в 2013 году, а песня — в 2020 году. ОСНОВНОЙ ИНТЕНТ: Найти видео со стихотворением или песней «Моя любовь к тебе чиста». ВТОРИЧНЫЙ ИНТЕНТ: ['Посмотреть исполнение песни «Моя любовь к тебе чиста» (версия 2020 года).', 'Найти видео с декламацией стихотворения «Моя любовь к тебе чиста».', 'Узнать больше о творчестве автора «Не Обязательно».'] | E72: Открыть HTML | F72: ок | G72: enling | H72: Нет | I72: Yandex 12.10 | J72: 3 | K72: 4 | L72: Нет | M72: у обоих серпов | N72: Выдачи практически одинаковые, у каждой по 1 видео с Youtube. Разница в урле, где в версии 04.10 ремикс на песню (не решает основной интент), а в выдаче 12.10 оригинал песни.
A73: каламити как получить искрящаяся императрица | B73: Москва (213) | C73: DESKTOP | D73: О ЧЕМ ЗАПРОС: Запрос связан с получением магического оружия «Искрящаяся императрица» в моде Calamity для игры Terraria. Оружие можно получить во время рыбалки в Затерянном море с определенным шансом после выполнения определенного условия. ОСНОВНОЙ ИНТЕНТ: Найти видео, объясняющее, как получить оружие «Искрящаяся императрица» в моде Calamity для Terraria, включая условия и процесс рыбалки в Затерянном море. ВТОРИЧНЫЙ ИНТЕНТ: ['Посмотреть обзор или демонстрацию оружия «Искрящаяся императрица» в действии.', 'Узнать альтернативные способы получения оружия или похожих предметов в моде Calamity.', 'Найти гайды по прохождению Пустынного бича, чтобы выполнить условие для получения оружия.'] | E73: Открыть HTML | F73: ок | G73: enling | H73: Нет | I73: Ничья | J73: 2 | K73: 2 | L73: Нет | M73: у обоих серпов | N73: Одинаковые видео, с тематикой игры, но нет ничего про нужное оружие. В каждой выдаче по 1 Youtube видео.
A74: что такое экологически катастрофы | B74: Владивосток (75) | C74: ANDROID | D74: О ЧЕМ ЗАПРОС: Запрос посвящен экологическим катастрофам — масштабным событиям, наносящим значительный ущерб природе и жизни людей. Они могут быть вызваны как природными явлениями, так и антропогенными факторами. В описании приведены конкретные примеры таких катастроф с указанием их последствий. ОСНОВНОЙ ИНТЕНТ: Найти видео, объясняющее, что такое экологические катастрофы, с примерами и анализом их последствий. ВТОРИЧНЫЙ ИНТЕНТ: ['Посмотреть документальные фильмы или репортажи о конкретных экологических катастрофах (например, разлив нефти в Мексиканском заливе, авария в Бхопале).', 'Узнать о влиянии экологических катастроф на окружающую среду и здоровье людей через видеоматериалы.', 'Найти образовательные ролики о предотвращении экологических катастроф и методах борьбы с их последствиями.'] | E74: Открыть HTML | F74: ок | G74: frolz-sk | H74: Нет | I74: Yandex 04.10 | J74: 4 | K74: 3 | L74: Нет | M74: у обоих серпов | N74: Пользователь ищет объяснение, что такое экологические катастрофы. Прямое определение есть только в A5 - презентации библиотеки на VK: экологическая катастрофа названа необратимым изменением природных комплексов, после чего приведены примеры с 1952 по 2011 год. A3/B3 - урок "ИнтернетУрока" о загрязнении атмосферы, озоновых дырах, кислотных дождях и парниковом эффекте. Остальные общие ролики (A1/B2, A2/B1 и A4/B5) в основном перечисляют известные катастрофы, поэтому отвечают на вопрос лишь частично. Четыре видео в выдачах совпадают. Различается один результат: слева есть A5 с прямым определением, а справа стоит B4, доступ к которому ограничил автор. Ранжирование справа тоже хуже: подборка с YouTube находится на первом месте, а учебный ролик только на третьем. Поэтому левая выдача лучше решает задачу. YouTube здесь не нужен: тему достаточно раскрывают ролики на VK и Rutube, а подборка KoToLaPa не даёт уникальной информации. Архивные кадры последствий катастроф показаны в образовательном контексте и не считаются критическим дефектом. Итог: слабая победа 04.10
A75: как сделать красивый обработки в гаче лайф | B75: Мурманск (23) | C75: ANDROID | D75: О ЧЕМ ЗАПРОС: Запрос касается создания и настройки персонажей в игре Gacha Life, включая изменение внешности, одежды и аксессуаров. Также упоминаются приложения для дополнительного редактирования изображений. ОСНОВНОЙ ИНТЕНТ: Найти видеоинструкцию по созданию и настройке персонажей в Gacha Life, включая изменение внешности, одежды и аксессуаров. ВТОРИЧНЫЙ ИНТЕНТ: ['Посмотреть обзоры приложений для редактирования изображений персонажей Gacha Life (например, Magisto, Afterlight, Snapseed).', 'Узнать о дополнительных функциях и возможностях настройки в Gacha Life, не упомянутых в основном запросе.', 'Найти видео с примерами красиво оформленных персонажей в Gacha Life для вдохновения.'] | E75: Открыть HTML | F75: ок | G75: purga89 | H75: Нет | I75: Ничья | J75: 4 | K75: 4 | L75: Нет | M75: у обоих серпов | N75: 12.10 - 1 ютуб, нет доступа 04.10 - 3 ютуб
A76: катастрофы фильмы | B76: Улькан (120257) | C76: DESKTOP | D76: О ЧЕМ ЗАПРОС: Запрос касается фильмов, посвященных катастрофам — природным или техногенным, как реальным, так и вымышленным. Пользователь, вероятно, хочет найти список или подборку таких фильмов для просмотра. ОСНОВНОЙ ИНТЕНТ: Найти и посмотреть фильмы-катастрофы (полные версии, подборки или трейлеры). ВТОРИЧНЫЙ ИНТЕНТ: ['Узнать о новых или популярных фильмах-катастрофах (например, для выбора что посмотреть).', 'Посмотреть трейлеры или обзоры фильмов-катастроф перед просмотром.', 'Найти фильмы, основанные на реальных катастрофах, для более глубокого понимания событий.'] | E76: Открыть HTML | F76: ок | G76: abraamian | H76: Нет | I76: Ничья | J76: 5 | K76: 5 | L76: Нет | M76: нет | N76: В выдачах 2 одинаковых фильма, остальные - разные. В выдаче 04.10 больше современных, а в выдаче 12.10 топ-5 фильм 1993 года в соответствующем качестве. Мы не можем утверждать, что пользователя интересуют только новинки, поэтому выдачи равны по релевантности.
A77: bon voyage " 1 сезон втс русская озвучка 8 | B77: Сибирский федеральный округ (59) | C77: DESKTOP | D77: О ЧЕМ ЗАПРОС: Запрос касается 8-й серии первого сезона дорамы BTS Bon Voyage с русской озвучкой. BTS Bon Voyage — это реалити-шоу о путешествиях участников южнокорейского бойз-бэнда BTS, первый сезон которого вышел в 2016 году. ОСНОВНОЙ ИНТЕНТ: Найти и посмотреть 8-ю серию первого сезона дорамы BTS Bon Voyage с русской озвучкой. ВТОРИЧНЫЙ ИНТЕНТ: ['Найти альтернативные варианты перевода 8-й серии (например, «Зозя», «Коко Джамбо», «Риддл Спейс», «Зиппер»).', 'Узнать, где ещё доступен этот контент (например, YouTube, Яндекс Видео, DoramaTV).'] | E77: Открыть HTML | F77: ок | G77: abraamian | H77: Нет | I77: Yandex 04.10 | J77: 5 | K77: 5 | L77: Да | M77: только 12.10 | N77: Выдачи похожие, все видео решают основной интент. В 04.10 три уникальных видео по озвучке. В 12.10 добавляется четвертое уникальное видео с озвучкой от CocoJambo. У этого канала есть группа в ВК, поэтому наличие YouTube в выдаче является дефектом, но поскольку оно расположено на 5 строчке и может стать уникальным решением для пользователей с VPN, я считаю, что не стоит штрафовать выдачу. Слабая победа выдачи 04.10 по доступности.
A78: порно в драке | B78: Новокуйбышевск (11135) | C78: IPHONE | D78: О ЧЕМ ЗАПРОС: Запрос связан с поиском видео порнографического содержания, где присутствуют элементы драки или борьбы. Контент предназначен только для взрослых. ОСНОВНОЙ ИНТЕНТ: Найти видео порнографического характера с элементами драки или борьбы. ВТОРИЧНЫЙ ИНТЕНТ: ['Посмотреть альтернативные видео с похожей тематикой (например, борьба или доминирование).', 'Найти сайты или платформы, специализирующиеся на подобном контенте.'] | E78: Открыть HTML | F78: ок | G78: abraamian | H78: Нет | I78: Yandex 04.10 | J78: 5 | K78: 4 | L78: Да | M78: нет | N78: Обе выдачи релевантные, но в новой выдаче 12.10 в топ-5 подтянулось видео с PornHub, которое не загружается без VPN. Выдача 04.10 лучше.
A79: братишкин и маления | B79: Якутск (74) | C79: ANDROID | D79: О ЧЕМ ЗАПРОС: Запрос касается события в игровом сообществе, связанного с победой стримера Bratishkin над боссом Маленией в игре Elden Ring. Пользователь, вероятно, ищет видео, связанное с этим событием или с игровым процессом Bratishkin. ОСНОВНОЙ ИНТЕНТ: Найти видео, где Bratishkin побеждает Малению в Elden Ring или связанные с этим событием. ВТОРИЧНЫЙ ИНТЕНТ: ['Посмотреть обзоры или комментарии к игре Elden Ring, связанные с боссом Маленией.', 'Найти другие видео с канала Bratishkin Rofls, связанные с Elden Ring.'] | E79: Открыть HTML | F79: ок | G79: purga89 | H79: Нет | I79: Ничья | J79: 4 | K79: 4 | L79: Нет | M79: у обоих серпов | N79: 12.10 - 2 видео ютуб 04.10 - 3 видео ютуб
...

Sheet Sheet5
B1: Информация о запросе | E1: Прокачка | G1: Разметка AI-тренера
A2: query | B2: region | C2: device | D2: likbez | E2: url | F2: ок / не ок | G2: login | H2: Баг прокачки? | I2: Кто выиграл | J2: Оценка Yandex 04.10 | K2: Оценка Yandex 12.10 | L2: Поиск сломанный 12.10? | M2: Проблемы с Youtube | N2: Комментарий
A3: чем закончится игра в кальмара 3сезон | B3: Центральный федеральный округ (3) | C3: ANDROID | D3: О ЧЕМ ЗАПРОС: Запрос касается возможного завершения 3 сезона южнокорейского сериала «Игра в кальмара» (2021, режиссёр Хван Дон Хёк). Однако на данный момент существует только 1 сезон, и о выходе 3 сезона официальных данных нет. ОСНОВНОЙ ИНТЕНТ: Посмотреть видео с разбором или предположениями о возможном завершении 3 сезона сериала «Игра в кальмара» (если такие видео существуют). ВТОРИЧНЫЙ ИНТЕНТ: ['Найти видео с обсуждением финала 1 сезона «Игры в кальмара» (так как 3 сезон не существует).', 'Посмотреть трейлеры, интервью или новости о возможном продолжении сериала.', 'Узнать фанатские теории или спойлеры о развитии сюжета, если бы 3 сезон был снят.'] | E3: Открыть HTML | F3: ок | G3: torbakhov
A4: новые видио рыжива ката | B4: Калининград (22) | C4: DESKTOP | D4: О ЧЕМ ЗАПРОС: Пользователь ищет новые видео, связанные с 'рыжива ката'. Точный контекст или значение этого термина неизвестны, возможно, это опечатка или узкоспециализированный запрос. ОСНОВНОЙ ИНТЕНТ: Найти новые видео, связанные с 'рыжива ката' (возможно, опечатка или специфический термин). ВТОРИЧНЫЙ ИНТЕНТ: ["Найти видео с похожими или альтернативными названиями, если 'рыжива ката' — опечатка.", "Найти обзоры или поясняющие ролики, если 'рыжива ката' — это термин из какой-либо нишевой тематики."] | E4: Открыть HTML | F4: ок | G4: torbakhov
A5: дай мне посмотреть | B5: Южный федеральный округ (26) | C5: DESKTOP | D5: О ЧЕМ ЗАПРОС: Запрос связан с поиском видео, содержащего трек «Дай мне посмотреть» (Let Me See) от Bushido Zho и Heronwater, выпущенный в 2023 году. ОСНОВНОЙ ИНТЕНТ: Найти видео с треком «Дай мне посмотреть» (Let Me See) для прослушивания или просмотра клипа. ВТОРИЧНЫЙ ИНТЕНТ: ['Посмотреть клип или музыкальное видео на этот трек, если оно существует.', 'Найти живые выступления или каверы на этот трек.', 'Узнать больше о Bushido Zho и Heronwater, связанные с этим треком.'] | E5: Открыть HTML | F5: ок | G5: torbakhov
A6: зубарев | B6: Тула (15) | C6: DESKTOP | D6: О ЧЕМ ЗАПРОС: Запрос относится к Александру Зубареву — видеоблогеру, тиктокеру и стримеру, известному своими роликами о жизни в Китае, местной культуре и быте. Он также участвовал в различных шоу и снимается в кино. ОСНОВНОЙ ИНТЕНТ: Найти видео с Александром Зубаревым: его блоги, стримы, выступления в шоу или ролики о жизни в Китае. ВТОРИЧНЫЙ ИНТЕНТ: ['Посмотреть интервью или участия Зубарева в шоу (например, «Плюшки», «Вопрос ребром»).', 'Узнать о его личной жизни или творческих проектах (например, фильм «Скуф»).', 'Найти контент, связанный с культурой и бытом Китая, в его подаче.'] | E6: Открыть HTML | F6: ок | G6: torbakhov
A7: купить подарки аватария | B7: Самара (51) | C7: IPHONE | D7: О ЧЕМ ЗАПРОС: Запрос связан с поиском способов приобретения виртуальных подарков для игры «Аватария». Пользователь, вероятно, хочет найти магазины или сервисы, где можно купить внутриигровые подарки. ОСНОВНОЙ ИНТЕНТ: Найти видео с обзором или инструкцией, как и где купить подарки в игре «Аватария». ВТОРИЧНЫЙ ИНТЕНТ: ['Посмотреть видео о том, как работают магазины подарков в «Аватарии» (например, обзор Telegram-каналов или сайтов).', 'Узнать о промокодах или акциях, связанных с подарками в игре, через видео-контент.', 'Найти видео с отзывами или рекомендациями о покупке подарков в «Аватарии».'] | E7: Открыть HTML | F7: ок | G7: torbakhov
A8: можно ли использовать аккаунт huawei в смартфоне другой м | B8: Санкт-Петербург (2) | C8: ANDROID | D8: О чем запрос: можно ли использовать аккаунт huawei в смартфоне другой м Основной интент: видео с ответом на вопрос Вторичный интент: | E8: Открыть HTML | F8: ок | G8: torbakhov
A9: кто тебе это сказал виа караоке | B9: Уфа (172) | C9: DESKTOP | D9: О ЧЕМ ЗАПРОС: Запрос связан с поиском видео караоке-версии песни «Кто тебе сказал» в исполнении ВИА «Лейся, песня!». ОСНОВНОЙ ИНТЕНТ: Найти видео с караоке-версией песни «Кто тебе сказал» ВИА «Лейся, песня!» для прослушивания или исполнения. ВТОРИЧНЫЙ ИНТЕНТ: ['Посмотреть оригинальное исполнение песни «Кто тебе сказал» ВИА «Лейся, песня!»', 'Найти другие караоке-версии песен ВИА «Лейся, песня!»', 'Узнать больше о творчестве ВИА «Лейся, песня!»'] | E9: Открыть HTML | F9: ок | G9: torbakhov
A10: audi lucky blocks моды из ярика лапы | B10: Городской округ Орехово-Зуево (120990) | C10: DESKTOP | D10: О ЧЕМ ЗАПРОС: Запрос связан с модами для игры Minecraft, в частности с модификацией Lucky Blocks, которая добавляет в игру блоки удачи с различными случайными событиями. Возможно, пользователь ищет видео, связанные с установкой, обзором или геймплеем этих модов. ОСНОВНОЙ ИНТЕНТ: Найти видео, связанные с модом Lucky Blocks для Minecraft, возможно, обзоры, геймплей или инструкции по установке. ВТОРИЧНЫЙ ИНТЕНТ: ["Посмотреть видео с геймплеем мода Youtuber's Lucky Blocks", 'Найти обзоры на различные версии мода Lucky Blocks', 'Узнать, как установить мод Lucky Blocks в Minecraft'] | E10: Открыть HTML | F10: ок | G10: torbakhov
A11: разбили китайца, моя жизнь изменится навсегда - 11 часть | B11: Россия (225) | C11: DESKTOP | D11: О ЧЕМ ЗАПРОС: Пользователь ищет 11-ю часть видео, связанного с событием или историей под названием «Разбили китайца, моя жизнь изменится навсегда». Контекст запроса указывает на то, что это может быть серия из какого-то веб-сериала, блог-поста или документального рассказа, где описывается значимое событие в жизни автора или героя. ОСНОВНОЙ ИНТЕНТ: Найти и посмотреть 11-ю часть видео «Разбили китайца, моя жизнь изменится навсегда». ВТОРИЧНЫЙ ИНТЕНТ: ['Узнать больше о предыдущих или последующих частях этого видео (если таковые существуют).', 'Понять контекст или содержание всей серии, чтобы разобраться в сюжете.'] | E11: Открыть HTML | F11: ок | G11: torbakhov
A12: джигеротта грешница | B12: Кострома (7) | C12: ANDROID | D12: О ЧЕМ ЗАПРОС: Запрос посвящён персонажу Джиггероте Грешнице из сериала «Лексс» (1997–2002), её роли в сюжете и ключевым моментам появления в сериале. ОСНОВНОЙ ИНТЕНТ: Найти видео с участием Джиггероты Грешницы в сериале «Лексс» (эпизоды, сцены, моменты с её участием). ВТОРИЧНЫЙ ИНТЕНТ: ['Посмотреть обзоры или анализ персонажа Джиггероты (например, её влияние на сюжет, особенности поведения).', 'Узнать больше об актрисе Эллен Дубин и её работе над ролью (интервью, закулисные материалы).', 'Найти трейлеры или фрагменты сериала «Лексс», где фигурирует Джиггерота.'] | E12: Открыть HTML | F12: ок | G12: torbakhov
A13: геннадий синицын маньяк | B13: Рязань (11) | C13: IPHONE | D13: О ЧЕМ ЗАПРОС: Запрос касается Геннадия Синицына, серийного маньяка из Волгограда, обвиняемого в серии изнасилований и убийств в прошлом. Он был осужден, но позже срок заменили на 15 лет колонии, после чего он вышел на свободу. ОСНОВНОЙ ИНТЕНТ: Найти видео о Геннадии Синицыне, его преступлениях, суде и последующем освобождении (документальные фильмы, репортажи, интервью). ВТОРИЧНЫЙ ИНТЕНТ: ['Посмотреть криминальные анализы или расследования его дела.', 'Узнать о реакции общества и СМИ на его преступления и освобождение.', 'Найти интервью с жертвами, свидетелями или экспертами по этому делу.'] | E13: Открыть HTML | F13: ок | G13: vliseev
A14: как узнать что порвана подушка двигателя лексус джи эс 300 2006 | B14: Астрахань (37) | C14: ANDROID | D14: О ЧЕМ ЗАПРОС: Запрос касается диагностики неисправности подушек двигателя в автомобиле Lexus GS 300 2006 года. Пользователь хочет узнать признаки, указывающие на повреждение подушек двигателя. ОСНОВНОЙ ИНТЕНТ: Найти видео с инструкцией или объяснением, как определить, что подушка двигателя Lexus GS 300 2006 года порвана. ВТОРИЧНЫЙ ИНТЕНТ: ['Посмотреть видео с обзором общих признаков неисправности подушек двигателя в автомобилях.', 'Найти видео с демонстрацией замены подушек двигателя на Lexus GS 300.', 'Посмотреть видео с советами по диагностике автомобильных неисправностей своими руками.'] | E14: Открыть HTML | F14: ок | G14: vliseev
... A102: золотое дно сериал с 2024 г. актёры | B102: Краснодар (35) | C102: IPHONE | D102: О ЧЕМ ЗАПРОС: Запрос касается актёрского состава сериала «Золотое дно», который вышел в 2024 году. Пользователь хочет узнать, кто играет главные роли в этом сериале. ОСНОВНОЙ ИНТЕНТ: Найти видео с информацией об актёрском составе сериала «Золотое дно» (2024), включая имена актёров и их роли. ВТОРИЧНЫЙ ИНТЕНТ: ['Посмотреть трейлер или отрывки из сериала с участием конкретных актёров.', 'Узнать дополнительную информацию о сериале, например, сюжет или рейтинги.', 'Найти интервью или закулисные материалы с актёрами сериала.'] | E102: Открыть HTML | F102: ок | G102: vadimshub
